<?xml version="1.0" encoding="utf-8"?>
<!-- =================================================================================== -->
<!-- |    This document was autogenerated by xacro from simpleEVA.urdf.xacro           | -->
<!-- |    EDITING THIS FILE BY HAND IS NOT RECOMMENDED                                 | -->
<!-- =================================================================================== -->
<!-- Joint angles, link lengths and mass all found from Automata documentation -->
<robot name="simpleEVA">
  <!-- offWhite colour -->
  <material name="offWhite">
    <color rgba="0.960784313725 0.960784313725 0.960784313725 1"/>
  </material>
  <!-- Black colour -->
  <material name="black">
    <color rgba="0.0 0.0 0.0 1"/>
  </material>
  <!-- Yellow colour -->
  <material name="yellow">
    <color rgba="1.0 1.0 0.0 1"/>
  </material>
  <!-- darkGrey colour -->
  <material name="darkGrey">
    <color rgba="0.662745098039 0.662745098039 0.662745098039 1"/>
  </material>
  <!-- 1st link -->
  <link name="link1">
    <inertial>
      <mass value="2.01189127973"/>
      <inertia ixx="0.00796591586448" ixy="0" ixz="0" iyy="0.00420619403549" iyz="0" izz="0.00796591586448"/>
    </inertial>
    <visual name="link1Visual">
      <geometry>
        <box size="0.112 0.112 0.187"/>
      </geometry>
      <origin rpy="0 0 0" xyz="0 0 0.0935"/>
      <material name="offWhite"/>
    </visual>
    <collision name="link1Collision">
      <geometry>
        <box size="0.112 0.112 0.187"/>
      </geometry>
      <origin rpy="0 0 0" xyz="0 0 0.0935"/>
    </collision>
  </link>
  <!-- 1st joint -->
  <joint name="joint1" type="revolute">
    <parent link="link1"/>
    <child link="link2"/>
    <limit effort="30" lower="-3.12413936107" upper="3.12413936107" velocity="1.0"/>
    <axis xyz="0 0 1"/>
    <origin rpy="0 0 0" xyz="0 0 0.187"/>
  </joint>
  <!-- "control box" -->
  <link name="controlBox">
    <visual name="controlBoxVisual">
      <geometry>
        <box size="0.075 0.11 0.078"/>
      </geometry>
      <origin rpy="0 0 0" xyz="0.056 0 0.039"/>
      <material name="darkGrey"/>
    </visual>
    <collision name="controlBoxCollision">
      <geometry>
        <box size="0.075 0.11 0.078"/>
      </geometry>
      <origin rpy="0 0 0" xyz="0.056 0 0.039"/>
    </collision>
  </link>
  <joint name="cBoxToLink1" type="fixed">
    <parent link="link1"/>
    <child link="controlBox"/>
  </joint>
  <!-- 2nd link -->
  <link name="link2">
    <inertial>
      <mass value="1.03284258211"/>
      <inertia ixx="0.000995660249151" ixy="0" ixz="0" iyy="0.000995660249151" iyz="0" izz="0.000404874292186"/>
    </inertial>
    <visual name="link2Visual">
      <geometry>
        <cylinder length="0.096" radius="0.028"/>
      </geometry>
      <origin rpy="0 0 0" xyz="0 0.028 0.048"/>
      <material name="offWhite"/>
    </visual>
    <collision name="link2Collision">
      <geometry>
        <cylinder length="0.096" radius="0.028"/>
      </geometry>
      <origin rpy="0 0 0" xyz="0 0.028 0.048"/>
    </collision>
  </link>
  <!-- 2nd joint -->
  <joint name="joint2" type="revolute">
    <parent link="link2"/>
    <child link="link3"/>
    <limit effort="30" lower="-2.70526034059" upper="1.2217304764" velocity="1.0"/>
    <axis xyz="0 1 0"/>
    <origin rpy="0 0 0" xyz="0 0 0.096"/>
  </joint>
  <!-- 3rd link -->
  <link name="link3">
    <inertial>
      <mass value="2.20554926387"/>
      <inertia ixx="0.00815630497357" ixy="0" ixz="0" iyy="0.00815630497357" iyz="0" izz="0.000864575311438"/>
    </inertial>
    <visual name="link3Visual">
      <geometry>
        <cylinder length="0.205" radius="0.028"/>
      </geometry>
      <origin rpy="0 0 0" xyz="0 -0.028 0.096"/>
      <material name="offWhite"/>
    </visual>
    <collision name="link3Collision">
      <geometry>
        <cylinder length="0.205" radius="0.028"/>
      </geometry>
      <origin rpy="0 0 0" xyz="0 -0.028 0.096"/>
    </collision>
  </link>
  <!-- 3rd joint -->
  <joint name="joint3" type="revolute">
    <parent link="link3"/>
    <child link="link4"/>
    <limit effort="30" lower="-2.79252680319" upper="0.785398163397" velocity="1.0"/>
    <axis xyz="0 1 0"/>
    <origin rpy="0 0 0" xyz="0 0 0.205"/>
  </joint>
  <!-- 4th link -->
  <link name="link4">
    <inertial>
      <mass value="1.33408833522"/>
      <inertia ixx="0.00197089316723" ixy="0" ixz="0" iyy="0.00197089316723" iyz="0" izz="0.000522962627407"/>
    </inertial>
    <visual name="link4Visual">
      <geometry>
        <cylinder length="0.124" radius="0.028"/>
      </geometry>
      <origin rpy="0 0 0" xyz="0 0.028 0.062"/>
      <material name="offWhite"/>
    </visual>
    <collision name="link4Collision">
      <geometry>
        <cylinder length="0.124" radius="0.028"/>
      </geometry>
      <origin rpy="0 0 0" xyz="0 0.028 0.062"/>
    </collision>
  </link>
  <!-- 4th joint -->
  <joint name="joint4" type="revolute">
    <parent link="link4"/>
    <child link="link5"/>
    <limit effort="30" lower="-3.12413936107" upper="3.12413936107" velocity="1.0"/>
    <axis xyz="0 0 1"/>
    <origin rpy="0 0 0" xyz="0 0 0.124"/>
  </joint>
  <!-- 5th link -->
  <link name="link5">
    <inertial>
      <mass value="1.79671574179"/>
      <inertia ixx="0.00558434225179" ixy="0" ixz="0" iyy="0.00558434225179" iyz="0" izz="0.00281725028313"/>
    </inertial>
    <visual name="link5Visual">
      <geometry>
        <cylinder length="0.167" radius="0.028"/>
      </geometry>
      <origin rpy="0 0 0" xyz="0 0 0.0835"/>
      <material name="offWhite"/>
    </visual>
    <collision name="link5Collision">
      <geometry>
        <cylinder length="0.167" radius="0.028"/>
      </geometry>
      <origin rpy="0 0 0" xyz="0 0 0.0835"/>
    </collision>
  </link>
  <!-- 5th joint -->
  <joint name="joint5" type="revolute">
    <parent link="link5"/>
    <child link="link6"/>
    <limit effort="30" lower="-2.70526034059" upper="0.174532925199" velocity="1.0"/>
    <axis xyz="0 1 0"/>
    <origin rpy="0 0 0" xyz="0 0 0.167"/>
  </joint>
  <!-- 6th link -->
  <link name="link6">
    <inertial>
      <mass value="1.11891279728"/>
      <inertia ixx="0.00130092261231" ixy="0" ixz="0" iyy="0.000584818422046" iyz="0" izz="0.00130092261231"/>
    </inertial>
    <visual name="link6Visual">
      <geometry>
        <box size="0.056 0.056 0.104"/>
      </geometry>
      <origin rpy="0 0 0" xyz="0.056 0 0.056"/>
      <material name="offWhite"/>
    </visual>
    <collision name="link6Collision">
      <geometry>
        <box size="0.056 0.056 0.104"/>
      </geometry>
      <origin rpy="0 0 0" xyz="0.056 0 0.056"/>
    </collision>
  </link>
  <!-- 6th joint -->
  <joint name="joint6" type="revolute">
    <parent link="link6"/>
    <child link="lamp"/>
    <limit effort="30" lower="-3.12413936107" upper="3.12413936107" velocity="1.0"/>
    <axis xyz="0 0 1"/>
    <origin rpy="0 0 0" xyz="0.056 0 0.104"/>
  </joint>
  <!-- Lamp -->
  <link name="lamp">
    <visual name="lampVisual">
      <geometry>
        <box size="0.066 0.066 0.065"/>
      </geometry>
      <origin rpy="0 0 0" xyz="0 0 0.0325"/>
      <material name="black"/>
    </visual>
    <collision name="lampCollision">
      <geometry>
        <box size="0.066 0.066 0.065"/>
      </geometry>
      <origin rpy="0 0 0" xyz="0 0 0.0325"/>
    </collision>
  </link>
  <!-- "bulb" -->
  <link name="bulb">
    <visual name="bulbVisual">
      <geometry>
        <cylinder length="0.01" radius="0.015"/>
      </geometry>
      <origin rpy="0 0 0" xyz="0 0 0.06"/>
      <material name="yellow"/>
    </visual>
    <collision name="bulbCollision">
      <geometry>
        <cylinder length="0.01" radius="0.015"/>
      </geometry>
      <origin rpy="0 0 0" xyz="0 0 0.06"/>
    </collision>
  </link>
  <joint name="bulbToLamp" type="fixed">
    <parent link="lamp"/>
    <child link="bulb"/>
  </joint>
</robot>

